[2025-08-12T12:18:57.603+0000] {local_task_job_runner.py:120} INFO - ::group::Pre task execution logs
[2025-08-12T12:18:57.768+0000] {taskinstance.py:2076} INFO - Dependencies all met for dep_context=non-requeueable deps ti=<TaskInstance: crypto_hourly_pipeline.ingest_cmc scheduled__2025-08-12T10:00:00+00:00 [queued]>
[2025-08-12T12:18:57.782+0000] {taskinstance.py:2076} INFO - Dependencies all met for dep_context=requeueable deps ti=<TaskInstance: crypto_hourly_pipeline.ingest_cmc scheduled__2025-08-12T10:00:00+00:00 [queued]>
[2025-08-12T12:18:57.782+0000] {taskinstance.py:2306} INFO - Starting attempt 2 of 2
[2025-08-12T12:18:57.805+0000] {taskinstance.py:2330} INFO - Executing <Task(BashOperator): ingest_cmc> on 2025-08-12 10:00:00+00:00
[2025-08-12T12:18:57.837+0000] {standard_task_runner.py:90} INFO - Running: ['***', 'tasks', 'run', 'crypto_hourly_pipeline', 'ingest_cmc', 'scheduled__2025-08-12T10:00:00+00:00', '--job-id', '7', '--raw', '--subdir', 'DAGS_FOLDER/crypto_pipeline.py', '--cfg-path', '/tmp/tmp_xhzl1ln']
[2025-08-12T12:18:57.842+0000] {standard_task_runner.py:91} INFO - Job 7: Subtask ingest_cmc
[2025-08-12T12:18:57.842+0000] {logging_mixin.py:188} WARNING - /home/***/.local/lib/python3.12/site-packages/***/task/task_runner/standard_task_runner.py:61 DeprecationWarning: This process (pid=495) is multi-threaded, use of fork() may lead to deadlocks in the child.
[2025-08-12T12:18:57.847+0000] {standard_task_runner.py:63} INFO - Started process 500 to run task
[2025-08-12T12:18:58.055+0000] {task_command.py:426} INFO - Running <TaskInstance: crypto_hourly_pipeline.ingest_cmc scheduled__2025-08-12T10:00:00+00:00 [running]> on host 93b3870592ea
[2025-08-12T12:18:58.213+0000] {taskinstance.py:2648} INFO - Exporting env vars: AIRFLOW_CTX_DAG_OWNER='***' AIRFLOW_CTX_DAG_ID='crypto_hourly_pipeline' AIRFLOW_CTX_TASK_ID='ingest_cmc' AIRFLOW_CTX_EXECUTION_DATE='2025-08-12T10:00:00+00:00' AIRFLOW_CTX_TRY_NUMBER='2' AIRFLOW_CTX_DAG_RUN_ID='scheduled__2025-08-12T10:00:00+00:00'
[2025-08-12T12:18:58.214+0000] {taskinstance.py:430} INFO - ::endgroup::
[2025-08-12T12:18:58.243+0000] {subprocess.py:63} INFO - Tmp dir root location: /tmp
[2025-08-12T12:18:58.246+0000] {subprocess.py:75} INFO - Running command: ['/usr/bin/bash', '-c', 'cd /opt/***/project && python ingest_cmc.py']
[2025-08-12T12:18:58.258+0000] {subprocess.py:86} INFO - Output:
[2025-08-12T12:18:59.303+0000] {subprocess.py:93} INFO - 2025-08-12 12:18:59,302 - INFO - Fetching data from CoinMarketCap API...
[2025-08-12T12:19:00.108+0000] {subprocess.py:93} INFO - 2025-08-12 12:19:00,106 - INFO - Successfully fetched 100 cryptocurrencies
[2025-08-12T12:19:00.116+0000] {subprocess.py:93} INFO - 2025-08-12 12:19:00,113 - INFO - Processed 100 records
[2025-08-12T12:19:00.147+0000] {subprocess.py:93} INFO - 2025-08-12 12:19:00,147 - ERROR - Error inserting data: connection failed: connection to server at "127.0.0.1", port 5433 failed: Connection refused
[2025-08-12T12:19:00.148+0000] {subprocess.py:93} INFO - 	Is the server running on that host and accepting TCP/IP connections?
[2025-08-12T12:19:00.148+0000] {subprocess.py:93} INFO - Multiple connection attempts failed. All failures were:
[2025-08-12T12:19:00.148+0000] {subprocess.py:93} INFO - - host: 'localhost', port: 5433, hostaddr: '::1': connection failed: connection to server at "::1", port 5433 failed: Connection refused
[2025-08-12T12:19:00.149+0000] {subprocess.py:93} INFO - 	Is the server running on that host and accepting TCP/IP connections?
[2025-08-12T12:19:00.150+0000] {subprocess.py:93} INFO - - host: 'localhost', port: 5433, hostaddr: '127.0.0.1': connection failed: connection to server at "127.0.0.1", port 5433 failed: Connection refused
[2025-08-12T12:19:00.150+0000] {subprocess.py:93} INFO - 	Is the server running on that host and accepting TCP/IP connections?
[2025-08-12T12:19:00.150+0000] {subprocess.py:93} INFO - 2025-08-12 12:19:00,147 - ERROR - Data ingestion failed: connection failed: connection to server at "127.0.0.1", port 5433 failed: Connection refused
[2025-08-12T12:19:00.151+0000] {subprocess.py:93} INFO - 	Is the server running on that host and accepting TCP/IP connections?
[2025-08-12T12:19:00.155+0000] {subprocess.py:93} INFO - Multiple connection attempts failed. All failures were:
[2025-08-12T12:19:00.157+0000] {subprocess.py:93} INFO - - host: 'localhost', port: 5433, hostaddr: '::1': connection failed: connection to server at "::1", port 5433 failed: Connection refused
[2025-08-12T12:19:00.158+0000] {subprocess.py:93} INFO - 	Is the server running on that host and accepting TCP/IP connections?
[2025-08-12T12:19:00.160+0000] {subprocess.py:93} INFO - - host: 'localhost', port: 5433, hostaddr: '127.0.0.1': connection failed: connection to server at "127.0.0.1", port 5433 failed: Connection refused
[2025-08-12T12:19:00.160+0000] {subprocess.py:93} INFO - 	Is the server running on that host and accepting TCP/IP connections?
[2025-08-12T12:19:00.161+0000] {subprocess.py:93} INFO - Traceback (most recent call last):
[2025-08-12T12:19:00.162+0000] {subprocess.py:93} INFO -   File "/opt/***/project/ingest_cmc.py", line 121, in <module>
[2025-08-12T12:19:00.165+0000] {subprocess.py:93} INFO -     main()
[2025-08-12T12:19:00.166+0000] {subprocess.py:93} INFO -     ^^^^^^
[2025-08-12T12:19:00.171+0000] {subprocess.py:93} INFO -   File "/opt/***/project/ingest_cmc.py", line 112, in main
[2025-08-12T12:19:00.172+0000] {subprocess.py:93} INFO -     insert_to_postgres(processed_data)
[2025-08-12T12:19:00.173+0000] {subprocess.py:93} INFO -   File "/opt/***/project/ingest_cmc.py", line 80, in insert_to_postgres
[2025-08-12T12:19:00.174+0000] {subprocess.py:93} INFO -     with psycopg.connect(**DB_CONFIG) as conn:
[2025-08-12T12:19:00.176+0000] {subprocess.py:93} INFO -          ^^^^^^^^^^^^^^^^^^^^^^^^^^^^
[2025-08-12T12:19:00.177+0000] {subprocess.py:93} INFO -   File "/home/***/.local/lib/python3.12/site-packages/psycopg/connection.py", line 125, in connect
[2025-08-12T12:19:00.178+0000] {subprocess.py:93} INFO -     raise type(last_ex)("\n".join(lines)).with_traceback(None)
[2025-08-12T12:19:00.178+0000] {subprocess.py:93} INFO - psycopg.OperationalError: connection failed: connection to server at "127.0.0.1", port 5433 failed: Connection refused
[2025-08-12T12:19:00.178+0000] {subprocess.py:93} INFO - 	Is the server running on that host and accepting TCP/IP connections?
[2025-08-12T12:19:00.179+0000] {subprocess.py:93} INFO - Multiple connection attempts failed. All failures were:
[2025-08-12T12:19:00.179+0000] {subprocess.py:93} INFO - - host: 'localhost', port: 5433, hostaddr: '::1': connection failed: connection to server at "::1", port 5433 failed: Connection refused
[2025-08-12T12:19:00.180+0000] {subprocess.py:93} INFO - 	Is the server running on that host and accepting TCP/IP connections?
[2025-08-12T12:19:00.180+0000] {subprocess.py:93} INFO - - host: 'localhost', port: 5433, hostaddr: '127.0.0.1': connection failed: connection to server at "127.0.0.1", port 5433 failed: Connection refused
[2025-08-12T12:19:00.182+0000] {subprocess.py:93} INFO - 	Is the server running on that host and accepting TCP/IP connections?
[2025-08-12T12:19:00.337+0000] {subprocess.py:97} INFO - Command exited with return code 1
[2025-08-12T12:19:00.349+0000] {taskinstance.py:441} INFO - ::group::Post task execution logs
[2025-08-12T12:19:00.992+0000] {taskinstance.py:2905} ERROR - Task failed with exception
Traceback (most recent call last):
  File "/home/airflow/.local/lib/python3.12/site-packages/airflow/models/taskinstance.py", line 465, in _execute_task
    result = _execute_callable(context=context, **execute_callable_kwargs)
             ^^^^^^^^^^^^^^^^^^^^^^^^^^^^^^^^^^^^^^^^^^^^^^^^^^^^^^^^^^^^^
  File "/home/airflow/.local/lib/python3.12/site-packages/airflow/models/taskinstance.py", line 432, in _execute_callable
    return execute_callable(context=context, **execute_callable_kwargs)
           ^^^^^^^^^^^^^^^^^^^^^^^^^^^^^^^^^^^^^^^^^^^^^^^^^^^^^^^^^^^^
  File "/home/airflow/.local/lib/python3.12/site-packages/airflow/models/baseoperator.py", line 401, in wrapper
    return func(self, *args, **kwargs)
           ^^^^^^^^^^^^^^^^^^^^^^^^^^^
  File "/home/airflow/.local/lib/python3.12/site-packages/airflow/operators/bash.py", line 243, in execute
    raise AirflowException(
airflow.exceptions.AirflowException: Bash command failed. The command returned a non-zero exit code 1.
[2025-08-12T12:19:01.068+0000] {taskinstance.py:1206} INFO - Marking task as FAILED. dag_id=crypto_hourly_pipeline, task_id=ingest_cmc, run_id=scheduled__2025-08-12T10:00:00+00:00, execution_date=20250812T100000, start_date=20250812T121857, end_date=20250812T121901
[2025-08-12T12:19:01.100+0000] {standard_task_runner.py:110} ERROR - Failed to execute job 7 for task ingest_cmc (Bash command failed. The command returned a non-zero exit code 1.; 500)
[2025-08-12T12:19:01.141+0000] {local_task_job_runner.py:240} INFO - Task exited with return code 1
[2025-08-12T12:19:01.208+0000] {taskinstance.py:3503} INFO - 0 downstream tasks scheduled from follow-on schedule check
[2025-08-12T12:19:01.247+0000] {local_task_job_runner.py:222} INFO - ::endgroup::
