[2025-08-13T15:24:34.274+0000] {local_task_job_runner.py:120} INFO - ::group::Pre task execution logs
[2025-08-13T15:24:34.327+0000] {taskinstance.py:2076} INFO - Dependencies all met for dep_context=non-requeueable deps ti=<TaskInstance: crypto_hourly_pipeline.dbt_hourly_gainers scheduled__2025-08-13T14:00:00+00:00 [queued]>
[2025-08-13T15:24:34.332+0000] {taskinstance.py:2076} INFO - Dependencies all met for dep_context=requeueable deps ti=<TaskInstance: crypto_hourly_pipeline.dbt_hourly_gainers scheduled__2025-08-13T14:00:00+00:00 [queued]>
[2025-08-13T15:24:34.332+0000] {taskinstance.py:2306} INFO - Starting attempt 3 of 4
[2025-08-13T15:24:34.341+0000] {taskinstance.py:2330} INFO - Executing <Task(BashOperator): dbt_hourly_gainers> on 2025-08-13 14:00:00+00:00
[2025-08-13T15:24:34.346+0000] {standard_task_runner.py:90} INFO - Running: ['***', 'tasks', 'run', 'crypto_hourly_pipeline', 'dbt_hourly_gainers', 'scheduled__2025-08-13T14:00:00+00:00', '--job-id', '83', '--raw', '--subdir', 'DAGS_FOLDER/crypto_pipeline.py', '--cfg-path', '/tmp/tmpm_yvxnfc']
[2025-08-13T15:24:34.351+0000] {logging_mixin.py:188} WARNING - /home/***/.local/lib/python3.12/site-packages/***/task/task_runner/standard_task_runner.py:61 DeprecationWarning: This process (pid=474) is multi-threaded, use of fork() may lead to deadlocks in the child.
[2025-08-13T15:24:34.351+0000] {standard_task_runner.py:91} INFO - Job 83: Subtask dbt_hourly_gainers
[2025-08-13T15:24:34.352+0000] {standard_task_runner.py:63} INFO - Started process 475 to run task
[2025-08-13T15:24:34.384+0000] {task_command.py:426} INFO - Running <TaskInstance: crypto_hourly_pipeline.dbt_hourly_gainers scheduled__2025-08-13T14:00:00+00:00 [running]> on host 26ef60e976b3
[2025-08-13T15:24:34.456+0000] {taskinstance.py:2648} INFO - Exporting env vars: AIRFLOW_CTX_DAG_OWNER='***' AIRFLOW_CTX_DAG_ID='crypto_hourly_pipeline' AIRFLOW_CTX_TASK_ID='dbt_hourly_gainers' AIRFLOW_CTX_EXECUTION_DATE='2025-08-13T14:00:00+00:00' AIRFLOW_CTX_TRY_NUMBER='3' AIRFLOW_CTX_DAG_RUN_ID='scheduled__2025-08-13T14:00:00+00:00'
[2025-08-13T15:24:34.456+0000] {taskinstance.py:430} INFO - ::endgroup::
[2025-08-13T15:24:34.467+0000] {subprocess.py:63} INFO - Tmp dir root location: /tmp
[2025-08-13T15:24:34.468+0000] {subprocess.py:75} INFO - Running command: ['/usr/bin/bash', '-c', 'cd /opt/***/project/dbt && dbt deps && dbt run --select crypto_hourly_gainers']
[2025-08-13T15:24:34.472+0000] {subprocess.py:86} INFO - Output:
[2025-08-13T15:24:36.020+0000] {subprocess.py:93} INFO - [0m15:24:36  Running with dbt=1.7.19
[2025-08-13T15:24:36.125+0000] {subprocess.py:93} INFO - [0m15:24:36  Warning: No packages were found in packages.yml
[2025-08-13T15:24:36.126+0000] {subprocess.py:93} INFO - [0m15:24:36  Warning: No packages were found in packages.yml
[2025-08-13T15:24:38.549+0000] {subprocess.py:93} INFO - [0m15:24:38  Running with dbt=1.7.19
[2025-08-13T15:24:38.585+0000] {subprocess.py:93} INFO - [0m15:24:38  Encountered an error:
[2025-08-13T15:24:38.586+0000] {subprocess.py:93} INFO - Runtime Error
[2025-08-13T15:24:38.586+0000] {subprocess.py:93} INFO -   Credentials in profile "crypto_profile", target "dev" invalid: '8123' is not valid under any of the given schemas
[2025-08-13T15:24:39.455+0000] {subprocess.py:97} INFO - Command exited with return code 2
[2025-08-13T15:24:39.457+0000] {taskinstance.py:441} INFO - ::group::Post task execution logs
[2025-08-13T15:24:39.473+0000] {taskinstance.py:2905} ERROR - Task failed with exception
Traceback (most recent call last):
  File "/home/airflow/.local/lib/python3.12/site-packages/airflow/models/taskinstance.py", line 465, in _execute_task
    result = _execute_callable(context=context, **execute_callable_kwargs)
             ^^^^^^^^^^^^^^^^^^^^^^^^^^^^^^^^^^^^^^^^^^^^^^^^^^^^^^^^^^^^^
  File "/home/airflow/.local/lib/python3.12/site-packages/airflow/models/taskinstance.py", line 432, in _execute_callable
    return execute_callable(context=context, **execute_callable_kwargs)
           ^^^^^^^^^^^^^^^^^^^^^^^^^^^^^^^^^^^^^^^^^^^^^^^^^^^^^^^^^^^^
  File "/home/airflow/.local/lib/python3.12/site-packages/airflow/models/baseoperator.py", line 401, in wrapper
    return func(self, *args, **kwargs)
           ^^^^^^^^^^^^^^^^^^^^^^^^^^^
  File "/home/airflow/.local/lib/python3.12/site-packages/airflow/operators/bash.py", line 243, in execute
    raise AirflowException(
airflow.exceptions.AirflowException: Bash command failed. The command returned a non-zero exit code 2.
[2025-08-13T15:24:39.477+0000] {taskinstance.py:1206} INFO - Marking task as UP_FOR_RETRY. dag_id=crypto_hourly_pipeline, task_id=dbt_hourly_gainers, run_id=scheduled__2025-08-13T14:00:00+00:00, execution_date=20250813T140000, start_date=20250813T152434, end_date=20250813T152439
[2025-08-13T15:24:39.487+0000] {standard_task_runner.py:110} ERROR - Failed to execute job 83 for task dbt_hourly_gainers (Bash command failed. The command returned a non-zero exit code 2.; 475)
[2025-08-13T15:24:39.514+0000] {local_task_job_runner.py:240} INFO - Task exited with return code 1
[2025-08-13T15:24:39.528+0000] {taskinstance.py:3503} INFO - 0 downstream tasks scheduled from follow-on schedule check
[2025-08-13T15:24:39.529+0000] {local_task_job_runner.py:222} INFO - ::endgroup::
