[2025-08-12T13:14:31.364+0000] {local_task_job_runner.py:120} INFO - ::group::Pre task execution logs
[2025-08-12T13:14:31.389+0000] {taskinstance.py:2076} INFO - Dependencies all met for dep_context=non-requeueable deps ti=<TaskInstance: crypto_hourly_pipeline.ingest_cmc scheduled__2025-08-12T12:00:00+00:00 [queued]>
[2025-08-12T13:14:31.393+0000] {taskinstance.py:2076} INFO - Dependencies all met for dep_context=requeueable deps ti=<TaskInstance: crypto_hourly_pipeline.ingest_cmc scheduled__2025-08-12T12:00:00+00:00 [queued]>
[2025-08-12T13:14:31.394+0000] {taskinstance.py:2306} INFO - Starting attempt 1 of 2
[2025-08-12T13:14:31.415+0000] {taskinstance.py:2330} INFO - Executing <Task(BashOperator): ingest_cmc> on 2025-08-12 12:00:00+00:00
[2025-08-12T13:14:31.461+0000] {logging_mixin.py:188} WARNING - /home/***/.local/lib/python3.12/site-packages/***/task/task_runner/standard_task_runner.py:61 DeprecationWarning: This process (pid=543) is multi-threaded, use of fork() may lead to deadlocks in the child.
[2025-08-12T13:14:31.459+0000] {standard_task_runner.py:90} INFO - Running: ['***', 'tasks', 'run', 'crypto_hourly_pipeline', 'ingest_cmc', 'scheduled__2025-08-12T12:00:00+00:00', '--job-id', '10', '--raw', '--subdir', 'DAGS_FOLDER/crypto_pipeline.py', '--cfg-path', '/tmp/tmpzlh90crl']
[2025-08-12T13:14:31.461+0000] {standard_task_runner.py:63} INFO - Started process 544 to run task
[2025-08-12T13:14:31.461+0000] {standard_task_runner.py:91} INFO - Job 10: Subtask ingest_cmc
[2025-08-12T13:14:31.510+0000] {task_command.py:426} INFO - Running <TaskInstance: crypto_hourly_pipeline.ingest_cmc scheduled__2025-08-12T12:00:00+00:00 [running]> on host 93b3870592ea
[2025-08-12T13:14:31.597+0000] {taskinstance.py:2648} INFO - Exporting env vars: AIRFLOW_CTX_DAG_OWNER='***' AIRFLOW_CTX_DAG_ID='crypto_hourly_pipeline' AIRFLOW_CTX_TASK_ID='ingest_cmc' AIRFLOW_CTX_EXECUTION_DATE='2025-08-12T12:00:00+00:00' AIRFLOW_CTX_TRY_NUMBER='1' AIRFLOW_CTX_DAG_RUN_ID='scheduled__2025-08-12T12:00:00+00:00'
[2025-08-12T13:14:31.597+0000] {taskinstance.py:430} INFO - ::endgroup::
[2025-08-12T13:14:31.608+0000] {subprocess.py:63} INFO - Tmp dir root location: /tmp
[2025-08-12T13:14:31.615+0000] {subprocess.py:75} INFO - Running command: ['/usr/bin/bash', '-c', 'cd /opt/***/project && python ingest_cmc.py']
[2025-08-12T13:14:31.668+0000] {subprocess.py:86} INFO - Output:
[2025-08-12T13:14:33.663+0000] {subprocess.py:93} INFO - 2025-08-12 13:14:33,662 - INFO - Fetching data from CoinMarketCap API...
[2025-08-12T13:14:46.550+0000] {subprocess.py:93} INFO - 2025-08-12 13:14:46,545 - INFO - Fetching data from CoinMarketCap API...
[2025-08-12T14:37:05.920+0000] {subprocess.py:93} INFO - 2025-08-12 14:37:05,917 - INFO - Fetching data from CoinMarketCap API...
[2025-08-12T14:37:13.936+0000] {subprocess.py:93} INFO - 2025-08-12 14:37:13,934 - ERROR - Data ingestion failed: RetryError[<Future at 0xffff870ccfe0 state=finished raised ConnectionError>]
[2025-08-12T14:37:13.944+0000] {subprocess.py:93} INFO - Traceback (most recent call last):
[2025-08-12T14:37:13.945+0000] {subprocess.py:93} INFO -   File "/home/***/.local/lib/python3.12/site-packages/urllib3/connection.py", line 198, in _new_conn
[2025-08-12T14:37:13.946+0000] {subprocess.py:93} INFO -     sock = connection.create_connection(
[2025-08-12T14:37:13.946+0000] {subprocess.py:93} INFO -            ^^^^^^^^^^^^^^^^^^^^^^^^^^^^^
[2025-08-12T14:37:13.947+0000] {subprocess.py:93} INFO -   File "/home/***/.local/lib/python3.12/site-packages/urllib3/util/connection.py", line 60, in create_connection
[2025-08-12T14:37:13.947+0000] {subprocess.py:93} INFO -     for res in socket.getaddrinfo(host, port, family, socket.SOCK_STREAM):
[2025-08-12T14:37:13.947+0000] {subprocess.py:93} INFO -                ^^^^^^^^^^^^^^^^^^^^^^^^^^^^^^^^^^^^^^^^^^^^^^^^^^^^^^^^^^
[2025-08-12T14:37:13.948+0000] {subprocess.py:93} INFO -   File "/usr/local/lib/python3.12/socket.py", line 964, in getaddrinfo
[2025-08-12T14:37:13.948+0000] {subprocess.py:93} INFO -     for res in _socket.getaddrinfo(host, port, family, type, proto, flags):
[2025-08-12T14:37:13.948+0000] {subprocess.py:93} INFO -                ^^^^^^^^^^^^^^^^^^^^^^^^^^^^^^^^^^^^^^^^^^^^^^^^^^^^^^^^^^^
[2025-08-12T14:37:13.948+0000] {subprocess.py:93} INFO - socket.gaierror: [Errno -3] Temporary failure in name resolution
[2025-08-12T14:37:13.949+0000] {subprocess.py:93} INFO - 
[2025-08-12T14:37:13.949+0000] {subprocess.py:93} INFO - The above exception was the direct cause of the following exception:
[2025-08-12T14:37:13.949+0000] {subprocess.py:93} INFO - 
[2025-08-12T14:37:13.950+0000] {subprocess.py:93} INFO - Traceback (most recent call last):
[2025-08-12T14:37:13.950+0000] {subprocess.py:93} INFO -   File "/home/***/.local/lib/python3.12/site-packages/urllib3/connectionpool.py", line 793, in urlopen
[2025-08-12T14:37:13.950+0000] {subprocess.py:93} INFO -     response = self._make_request(
[2025-08-12T14:37:13.950+0000] {subprocess.py:93} INFO -                ^^^^^^^^^^^^^^^^^^^
[2025-08-12T14:37:13.951+0000] {subprocess.py:93} INFO -   File "/home/***/.local/lib/python3.12/site-packages/urllib3/connectionpool.py", line 491, in _make_request
[2025-08-12T14:37:13.951+0000] {subprocess.py:93} INFO -     raise new_e
[2025-08-12T14:37:13.951+0000] {subprocess.py:93} INFO -   File "/home/***/.local/lib/python3.12/site-packages/urllib3/connectionpool.py", line 467, in _make_request
[2025-08-12T14:37:13.952+0000] {subprocess.py:93} INFO -     self._validate_conn(conn)
[2025-08-12T14:37:13.952+0000] {subprocess.py:93} INFO -   File "/home/***/.local/lib/python3.12/site-packages/urllib3/connectionpool.py", line 1099, in _validate_conn
[2025-08-12T14:37:13.952+0000] {subprocess.py:93} INFO -     conn.connect()
[2025-08-12T14:37:13.956+0000] {subprocess.py:93} INFO -   File "/home/***/.local/lib/python3.12/site-packages/urllib3/connection.py", line 616, in connect
[2025-08-12T14:37:13.957+0000] {subprocess.py:93} INFO -     self.sock = sock = self._new_conn()
[2025-08-12T14:37:13.957+0000] {subprocess.py:93} INFO -                        ^^^^^^^^^^^^^^^^
[2025-08-12T14:37:13.957+0000] {subprocess.py:93} INFO -   File "/home/***/.local/lib/python3.12/site-packages/urllib3/connection.py", line 205, in _new_conn
[2025-08-12T14:37:13.957+0000] {subprocess.py:93} INFO -     raise NameResolutionError(self.host, self, e) from e
[2025-08-12T14:37:13.957+0000] {subprocess.py:93} INFO - urllib3.exceptions.NameResolutionError: <urllib3.connection.HTTPSConnection object at 0xffff870ccfb0>: Failed to resolve 'pro-api.coinmarketcap.com' ([Errno -3] Temporary failure in name resolution)
[2025-08-12T14:37:13.957+0000] {subprocess.py:93} INFO - 
[2025-08-12T14:37:13.958+0000] {subprocess.py:93} INFO - The above exception was the direct cause of the following exception:
[2025-08-12T14:37:13.958+0000] {subprocess.py:93} INFO - 
[2025-08-12T14:37:13.958+0000] {subprocess.py:93} INFO - Traceback (most recent call last):
[2025-08-12T14:37:13.958+0000] {subprocess.py:93} INFO -   File "/home/***/.local/lib/python3.12/site-packages/requests/adapters.py", line 486, in send
[2025-08-12T14:37:13.958+0000] {subprocess.py:93} INFO -     resp = conn.urlopen(
[2025-08-12T14:37:13.958+0000] {subprocess.py:93} INFO -            ^^^^^^^^^^^^^
[2025-08-12T14:37:13.958+0000] {subprocess.py:93} INFO -   File "/home/***/.local/lib/python3.12/site-packages/urllib3/connectionpool.py", line 847, in urlopen
[2025-08-12T14:37:13.959+0000] {subprocess.py:93} INFO -     retries = retries.increment(
[2025-08-12T14:37:13.959+0000] {subprocess.py:93} INFO -               ^^^^^^^^^^^^^^^^^^
[2025-08-12T14:37:13.959+0000] {subprocess.py:93} INFO -   File "/home/***/.local/lib/python3.12/site-packages/urllib3/util/retry.py", line 515, in increment
[2025-08-12T14:37:13.959+0000] {subprocess.py:93} INFO -     raise MaxRetryError(_pool, url, reason) from reason  # type: ignore[arg-type]
[2025-08-12T14:37:13.959+0000] {subprocess.py:93} INFO -     ^^^^^^^^^^^^^^^^^^^^^^^^^^^^^^^^^^^^^^^^^^^^^^^^^^^
[2025-08-12T14:37:13.959+0000] {subprocess.py:93} INFO - urllib3.exceptions.MaxRetryError: HTTPSConnectionPool(host='pro-api.coinmarketcap.com', port=443): Max retries exceeded with url: /v1/cryptocurrency/listings/latest?start=1&limit=100&convert=USD (Caused by NameResolutionError("<urllib3.connection.HTTPSConnection object at 0xffff870ccfb0>: Failed to resolve 'pro-api.coinmarketcap.com' ([Errno -3] Temporary failure in name resolution)"))
[2025-08-12T14:37:13.960+0000] {subprocess.py:93} INFO - 
[2025-08-12T14:37:13.960+0000] {subprocess.py:93} INFO - During handling of the above exception, another exception occurred:
[2025-08-12T14:37:13.961+0000] {subprocess.py:93} INFO - 
[2025-08-12T14:37:13.961+0000] {subprocess.py:93} INFO - Traceback (most recent call last):
[2025-08-12T14:37:13.962+0000] {subprocess.py:93} INFO -   File "/home/***/.local/lib/python3.12/site-packages/tenacity/__init__.py", line 470, in __call__
[2025-08-12T14:37:13.962+0000] {subprocess.py:93} INFO -     result = fn(*args, **kwargs)
[2025-08-12T14:37:13.962+0000] {subprocess.py:93} INFO -              ^^^^^^^^^^^^^^^^^^^
[2025-08-12T14:37:13.962+0000] {subprocess.py:93} INFO -   File "/opt/***/project/ingest_cmc.py", line 52, in fetch_cmc_data
[2025-08-12T14:37:13.962+0000] {subprocess.py:93} INFO -     response = requests.get(CMC_API_URL, headers=headers, params=params)
[2025-08-12T14:37:13.962+0000] {subprocess.py:93} INFO -                ^^^^^^^^^^^^^^^^^^^^^^^^^^^^^^^^^^^^^^^^^^^^^^^^^^^^^^^^^
[2025-08-12T14:37:13.962+0000] {subprocess.py:93} INFO -   File "/home/***/.local/lib/python3.12/site-packages/requests/api.py", line 73, in get
[2025-08-12T14:37:13.963+0000] {subprocess.py:93} INFO -     return request("get", url, params=params, **kwargs)
[2025-08-12T14:37:13.963+0000] {subprocess.py:93} INFO -            ^^^^^^^^^^^^^^^^^^^^^^^^^^^^^^^^^^^^^^^^^^^^
[2025-08-12T14:37:13.963+0000] {subprocess.py:93} INFO -   File "/home/***/.local/lib/python3.12/site-packages/requests/api.py", line 59, in request
[2025-08-12T14:37:13.963+0000] {subprocess.py:93} INFO -     return session.request(method=method, url=url, **kwargs)
[2025-08-12T14:37:13.963+0000] {subprocess.py:93} INFO -            ^^^^^^^^^^^^^^^^^^^^^^^^^^^^^^^^^^^^^^^^^^^^^^^^^
[2025-08-12T14:37:13.963+0000] {subprocess.py:93} INFO -   File "/home/***/.local/lib/python3.12/site-packages/requests/sessions.py", line 589, in request
[2025-08-12T14:37:13.963+0000] {subprocess.py:93} INFO -     resp = self.send(prep, **send_kwargs)
[2025-08-12T14:37:13.963+0000] {subprocess.py:93} INFO -            ^^^^^^^^^^^^^^^^^^^^^^^^^^^^^^
[2025-08-12T14:37:13.963+0000] {subprocess.py:93} INFO -   File "/home/***/.local/lib/python3.12/site-packages/requests/sessions.py", line 703, in send
[2025-08-12T14:37:13.965+0000] {subprocess.py:93} INFO -     r = adapter.send(request, **kwargs)
[2025-08-12T14:37:13.965+0000] {subprocess.py:93} INFO -         ^^^^^^^^^^^^^^^^^^^^^^^^^^^^^^^
[2025-08-12T14:37:13.967+0000] {subprocess.py:93} INFO -   File "/home/***/.local/lib/python3.12/site-packages/requests/adapters.py", line 519, in send
[2025-08-12T14:37:13.969+0000] {subprocess.py:93} INFO -     raise ConnectionError(e, request=request)
[2025-08-12T14:37:13.971+0000] {subprocess.py:93} INFO - requests.exceptions.ConnectionError: HTTPSConnectionPool(host='pro-api.coinmarketcap.com', port=443): Max retries exceeded with url: /v1/cryptocurrency/listings/latest?start=1&limit=100&convert=USD (Caused by NameResolutionError("<urllib3.connection.HTTPSConnection object at 0xffff870ccfb0>: Failed to resolve 'pro-api.coinmarketcap.com' ([Errno -3] Temporary failure in name resolution)"))
[2025-08-12T14:37:13.972+0000] {subprocess.py:93} INFO - 
[2025-08-12T14:37:13.972+0000] {subprocess.py:93} INFO - The above exception was the direct cause of the following exception:
[2025-08-12T14:37:13.972+0000] {subprocess.py:93} INFO - 
[2025-08-12T14:37:13.974+0000] {subprocess.py:93} INFO - Traceback (most recent call last):
[2025-08-12T14:37:13.975+0000] {subprocess.py:93} INFO -   File "/opt/***/project/ingest_cmc.py", line 121, in <module>
[2025-08-12T14:37:13.978+0000] {subprocess.py:93} INFO -     main()
[2025-08-12T14:37:13.988+0000] {subprocess.py:93} INFO -     ^^^^^^
[2025-08-12T14:37:13.990+0000] {subprocess.py:93} INFO -   File "/opt/***/project/ingest_cmc.py", line 106, in main
[2025-08-12T14:37:13.991+0000] {subprocess.py:93} INFO -     crypto_data = fetch_cmc_data()
[2025-08-12T14:37:13.992+0000] {subprocess.py:93} INFO -                   ^^^^^^^^^^^^^^^^
[2025-08-12T14:37:13.992+0000] {subprocess.py:93} INFO -   File "/home/***/.local/lib/python3.12/site-packages/tenacity/__init__.py", line 330, in wrapped_f
[2025-08-12T14:37:13.993+0000] {subprocess.py:93} INFO -     return self(f, *args, **kw)
[2025-08-12T14:37:13.993+0000] {subprocess.py:93} INFO -            ^^^^^^^^^^^^^^^^^^^^
[2025-08-12T14:37:13.995+0000] {subprocess.py:93} INFO -   File "/home/***/.local/lib/python3.12/site-packages/tenacity/__init__.py", line 467, in __call__
[2025-08-12T14:37:13.996+0000] {subprocess.py:93} INFO -     do = self.iter(retry_state=retry_state)
[2025-08-12T14:37:13.996+0000] {subprocess.py:93} INFO -          ^^^^^^^^^^^^^^^^^^^^^^^^^^^^^^^^^^
[2025-08-12T14:37:14.000+0000] {subprocess.py:93} INFO -   File "/home/***/.local/lib/python3.12/site-packages/tenacity/__init__.py", line 368, in iter
[2025-08-12T14:37:14.001+0000] {subprocess.py:93} INFO -     result = action(retry_state)
[2025-08-12T14:37:14.001+0000] {subprocess.py:93} INFO -              ^^^^^^^^^^^^^^^^^^^
[2025-08-12T14:37:14.002+0000] {subprocess.py:93} INFO -   File "/home/***/.local/lib/python3.12/site-packages/tenacity/__init__.py", line 411, in exc_check
[2025-08-12T14:37:14.002+0000] {subprocess.py:93} INFO -     raise retry_exc from fut.exception()
[2025-08-12T14:37:14.003+0000] {subprocess.py:93} INFO - tenacity.RetryError: RetryError[<Future at 0xffff870ccfe0 state=finished raised ConnectionError>]
[2025-08-12T14:37:14.090+0000] {subprocess.py:97} INFO - Command exited with return code 1
[2025-08-12T14:37:14.093+0000] {taskinstance.py:441} INFO - ::group::Post task execution logs
[2025-08-12T14:37:14.148+0000] {taskinstance.py:2905} ERROR - Task failed with exception
Traceback (most recent call last):
  File "/home/airflow/.local/lib/python3.12/site-packages/airflow/models/taskinstance.py", line 465, in _execute_task
    result = _execute_callable(context=context, **execute_callable_kwargs)
             ^^^^^^^^^^^^^^^^^^^^^^^^^^^^^^^^^^^^^^^^^^^^^^^^^^^^^^^^^^^^^
  File "/home/airflow/.local/lib/python3.12/site-packages/airflow/models/taskinstance.py", line 432, in _execute_callable
    return execute_callable(context=context, **execute_callable_kwargs)
           ^^^^^^^^^^^^^^^^^^^^^^^^^^^^^^^^^^^^^^^^^^^^^^^^^^^^^^^^^^^^
  File "/home/airflow/.local/lib/python3.12/site-packages/airflow/models/baseoperator.py", line 401, in wrapper
    return func(self, *args, **kwargs)
           ^^^^^^^^^^^^^^^^^^^^^^^^^^^
  File "/home/airflow/.local/lib/python3.12/site-packages/airflow/operators/bash.py", line 243, in execute
    raise AirflowException(
airflow.exceptions.AirflowException: Bash command failed. The command returned a non-zero exit code 1.
[2025-08-12T14:37:14.157+0000] {taskinstance.py:1206} INFO - Marking task as UP_FOR_RETRY. dag_id=crypto_hourly_pipeline, task_id=ingest_cmc, run_id=scheduled__2025-08-12T12:00:00+00:00, execution_date=20250812T120000, start_date=20250812T131431, end_date=20250812T143714
[2025-08-12T14:37:14.181+0000] {standard_task_runner.py:110} ERROR - Failed to execute job 10 for task ingest_cmc (Bash command failed. The command returned a non-zero exit code 1.; 544)
[2025-08-12T14:37:14.193+0000] {local_task_job_runner.py:240} INFO - Task exited with return code 1
[2025-08-12T14:37:14.304+0000] {taskinstance.py:3503} INFO - 0 downstream tasks scheduled from follow-on schedule check
[2025-08-12T14:37:14.306+0000] {local_task_job_runner.py:222} INFO - ::endgroup::
